Workbook

Sheet EJ_transactions
A1: Date | B1: Time | C1: POS_No | D1: Txn_ID | E1: Cashier_ID | F1: Order_ID | G1: Trip_ID | H1: Amount
A2: 46047 | B2: 0.37861111 | C2: POS01 | D2: TXN1001 | E2: C001 | H2: 245
A3: 46047 | B3: 0.38384259 | C3: POS02 | D3: TXN1002 | E3: C002 | H3: 780
A4: 46047 | B4: 0.38760417 | C4: POS03 | D4: TXN1003 | E4: C003 | H4: 120
A5: 46047 | B5: 0.39341435 | C5: POS01 | D5: TXN1004 | E5: C001 | F5: ORD5001 | G5: TRIP9001 | H5: 1560
A6: 46047 | B6: 0.40355324 | C6: POS02 | D6: TXN1005 | E6: C002 | H6: 340
A7: 46047 | B7: 0.41344907 | C7: POS03 | D7: TXN1006 | E7: C003 | H7: 2150
A8: 46047 | B8: 0.41895833 | C8: POS01 | D8: TXN1007 | E8: C001 | H8: 95
A9: 46047 | B9: 0.42770833 | C9: POS02 | D9: TXN1008 | E9: C002 | F9: ORD5002 | G9: TRIP9002 | H9: 890
A10: 46047 | B10: 0.43657407 | C10: POS03 | D10: TXN1009 | E10: C003 | H10: 460
A11: 46047 | B11: 0.44596065 | C11: POS01 | D11: TXN1010 | E11: C001 | H11: 1320
A12: 46047 | B12: 0.45489583 | C12: POS02 | D12: TXN1011 | E12: C002 | H12: 275
A13: 46047 | B13: 0.46376157 | C13: POS03 | D13: TXN1012 | E13: C003 | F13: ORD5003 | G13: TRIP9003 | H13: 2140
A14: 46047 | B14: 0.4718287 | C14: POS01 | D14: TXN1013 | E14: C001 | H14: 560
A15: 46047 | B15: 0.4819213 | C15: POS02 | D15: TXN1014 | E15: C002 | H15: 410
A16: 46047 | B16: 0.49178241 | C16: POS03 | D16: TXN1015 | E16: C003 | H16: 75
A17: 46047 | B17: 0.50189815 | C17: POS01 | D17: TXN1016 | E17: C001 | F17: ORD5004 | G17: TRIP9004 | H17: 3250
A18: 46047 | B18: 0.5128588 | C18: POS02 | D18: TXN1017 | E18: C002 | H18: 980
A19: 46047 | B19: 0.52424769 | C19: POS03 | D19: TXN1018 | E19: C003 | H19: 150
A20: 46047 | B20: 0.53491898 | C20: POS01 | D20: TXN1019 | E20: C001 | H20: 670
A21: 46047 | B21: 0.545625 | C21: POS02 | D21: TXN1020 | E21: C002 | F21: ORD5005 | G21: TRIP9005 | H21: 1240
A22: 46047 | B22: 0.55703704 | C22: POS03 | D22: TXN1021 | E22: C003 | H22: 210
A23: 46047 | B23: 0.5687037 | C23: POS01 | D23: TXN1022 | E23: C001 | H23: 1840
A24: 46047 | B24: 0.58010417 | C24: POS02 | D24: TXN1023 | E24: C002 | H24: -320
A25: 46047 | B25: 0.59012731 | C25: POS03 | D25: TXN1024 | E25: C003 | H25: 540
A26: 46047 | B26: 0.60038194 | C26: POS01 | D26: TXN1025 | E26: C001 | F26: ORD5006 | G26: TRIP9006 | H26: 2750
A27: 46047 | B27: 0.61131944 | C27: POS02 | D27: TXN1026 | E27: C002 | H27: 360
A28: 46047 | B28: 0.62155093 | C28: POS03 | D28: TXN1027 | E28: C003 | H28: 1120
A29: 46047 | B29: 0.63320602 | C29: POS01 | D29: TXN1028 | E29: C001 | H29: -450
A30: 46047 | B30: 0.64486111 | C30: POS02 | D30: TXN1029 | E30: C002 | F30: ORD5007 | G30: TRIP9007 | H30: 690
A31: 46047 | B31: 0.65641204 | C31: POS03 | D31: TXN1030 | E31: C003 | H31: 260
A32: 46047 | B32: 0.66872685 | C32: POS01 | D32: TXN1031 | E32: C001 | H32: 980
A33: 46047 | B33: 0.67943287 | C33: POS02 | D33: TXN1032 | E33: C002 | H33: 1430
A34: 46047 | B34: 0.69075231 | C34: POS03 | D34: TXN1033 | E34: C003 | F34: ORD5008 | G34: TRIP9008 | H34: 4120
A35: 46047 | B35: 0.70149306 | C35: POS01 | D35: TXN1034 | E35: C001 | H35: 180
A36: 46047 | B36: 0.71292824 | C36: POS02 | D36: TXN1035 | E36: C002 | H36: -210
A37: 46047 | B37: 0.72423611 | C37: POS03 | D37: TXN1036 | E37: C003 | H37: 760
A38: 46047 | B38: 0.73574074 | C38: POS01 | D38: TXN1037 | E38: C001 | F38: ORD5009 | G38: TRIP9009 | H38: 990
A39: 46047 | B39: 0.74706019 | C39: POS02 | D39: TXN1038 | E39: C002 | H39: 430
A40: 46047 | B40: 0.75855324 | C40: POS03 | D40: TXN1039 | E40: C003 | H40: 1580
...

Sheet Cleaned_EJ
A1: Date | B1: Time | C1: POS_No | D1: Txn_ID | E1: Cashier_ID | F1: Order_ID | G1: Trip_ID | H1: Amount | I1: Sales_Channel | J1: TXN_Type | K1: Abs_amount
A2: 46047 | B2: 0.37861111 | C2: POS01 | D2: TXN1001 | E2: C001 | H2: 245 | I2: =IF(F2="","OFFLINE","ONLINE") -> OFFLINE | J2: =IF(H2 < 0, "Return", "Sale") -> Sale | K2: =ABS(H2) -> 245
A3: 46047 | B3: 0.38384259 | C3: POS02 | D3: TXN1002 | E3: C002 | H3: 780 | I3: =IF(F3="","OFFLINE","ONLINE") -> OFFLINE | J3: =IF(H3 < 0, "Return", "Sale") -> Sale | K3: =ABS(H3) -> 780
A4: 46047 | B4: 0.38760417 | C4: POS03 | D4: TXN1003 | E4: C003 | H4: 120 | I4: =IF(F4="","OFFLINE","ONLINE") -> OFFLINE | J4: =IF(H4 < 0, "Return", "Sale") -> Sale | K4: =ABS(H4) -> 120
A5: 46047 | B5: 0.39341435 | C5: POS01 | D5: TXN1004 | E5: C001 | F5: ORD5001 | G5: TRIP9001 | H5: 1560 | I5: =IF(F5="","OFFLINE","ONLINE") -> ONLINE | J5: =IF(H5 < 0, "Return", "Sale") -> Sale | K5: =ABS(H5) -> 1560
A6: 46047 | B6: 0.40355324 | C6: POS02 | D6: TXN1005 | E6: C002 | H6: 340 | I6: =IF(F6="","OFFLINE","ONLINE") -> OFFLINE | J6: =IF(H6 < 0, "Return", "Sale") -> Sale | K6: =ABS(H6) -> 340
A7: 46047 | B7: 0.41344907 | C7: POS03 | D7: TXN1006 | E7: C003 | H7: 2150 | I7: =IF(F7="","OFFLINE","ONLINE") -> OFFLINE | J7: =IF(H7 < 0, "Return", "Sale") -> Sale | K7: =ABS(H7) -> 2150
A8: 46047 | B8: 0.41895833 | C8: POS01 | D8: TXN1007 | E8: C001 | H8: 95 | I8: =IF(F8="","OFFLINE","ONLINE") -> OFFLINE | J8: =IF(H8 < 0, "Return", "Sale") -> Sale | K8: =ABS(H8) -> 95
A9: 46047 | B9: 0.42770833 | C9: POS02 | D9: TXN1008 | E9: C002 | F9: ORD5002 | G9: TRIP9002 | H9: 890 | I9: =IF(F9="","OFFLINE","ONLINE") -> ONLINE | J9: =IF(H9 < 0, "Return", "Sale") -> Sale | K9: =ABS(H9) -> 890
A10: 46047 | B10: 0.43657407 | C10: POS03 | D10: TXN1009 | E10: C003 | H10: 460 | I10: =IF(F10="","OFFLINE","ONLINE") -> OFFLINE | J10: =IF(H10 < 0, "Return", "Sale") -> Sale | K10: =ABS(H10) -> 460
A11: 46047 | B11: 0.44596065 | C11: POS01 | D11: TXN1010 | E11: C001 | H11: 1320 | I11: =IF(F11="","OFFLINE","ONLINE") -> OFFLINE | J11: =IF(H11 < 0, "Return", "Sale") -> Sale | K11: =ABS(H11) -> 1320
A12: 46047 | B12: 0.45489583 | C12: POS02 | D12: TXN1011 | E12: C002 | H12: 275 | I12: =IF(F12="","OFFLINE","ONLINE") -> OFFLINE | J12: =IF(H12 < 0, "Return", "Sale") -> Sale | K12: =ABS(H12) -> 275
A13: 46047 | B13: 0.46376157 | C13: POS03 | D13: TXN1012 | E13: C003 | F13: ORD5003 | G13: TRIP9003 | H13: 2140 | I13: =IF(F13="","OFFLINE","ONLINE") -> ONLINE | J13: =IF(H13 < 0, "Return", "Sale") -> Sale | K13: =ABS(H13) -> 2140
A14: 46047 | B14: 0.4718287 | C14: POS01 | D14: TXN1013 | E14: C001 | H14: 560 | I14: =IF(F14="","OFFLINE","ONLINE") -> OFFLINE | J14: =IF(H14 < 0, "Return", "Sale") -> Sale | K14: =ABS(H14) -> 560
A15: 46047 | B15: 0.4819213 | C15: POS02 | D15: TXN1014 | E15: C002 | H15: 410 | I15: =IF(F15="","OFFLINE","ONLINE") -> OFFLINE | J15: =IF(H15 < 0, "Return", "Sale") -> Sale | K15: =ABS(H15) -> 410
A16: 46047 | B16: 0.49178241 | C16: POS03 | D16: TXN1015 | E16: C003 | H16: 75 | I16: =IF(F16="","OFFLINE","ONLINE") -> OFFLINE | J16: =IF(H16 < 0, "Return", "Sale") -> Sale | K16: =ABS(H16) -> 75
A17: 46047 | B17: 0.50189815 | C17: POS01 | D17: TXN1016 | E17: C001 | F17: ORD5004 | G17: TRIP9004 | H17: 3250 | I17: =IF(F17="","OFFLINE","ONLINE") -> ONLINE | J17: =IF(H17 < 0, "Return", "Sale") -> Sale | K17: =ABS(H17) -> 3250
A18: 46047 | B18: 0.5128588 | C18: POS02 | D18: TXN1017 | E18: C002 | H18: 980 | I18: =IF(F18="","OFFLINE","ONLINE") -> OFFLINE | J18: =IF(H18 < 0, "Return", "Sale") -> Sale | K18: =ABS(H18) -> 980
A19: 46047 | B19: 0.52424769 | C19: POS03 | D19: TXN1018 | E19: C003 | H19: 150 | I19: =IF(F19="","OFFLINE","ONLINE") -> OFFLINE | J19: =IF(H19 < 0, "Return", "Sale") -> Sale | K19: =ABS(H19) -> 150
A20: 46047 | B20: 0.53491898 | C20: POS01 | D20: TXN1019 | E20: C001 | H20: 670 | I20: =IF(F20="","OFFLINE","ONLINE") -> OFFLINE | J20: =IF(H20 < 0, "Return", "Sale") -> Sale | K20: =ABS(H20) -> 670
A21: 46047 | B21: 0.545625 | C21: POS02 | D21: TXN1020 | E21: C002 | F21: ORD5005 | G21: TRIP9005 | H21: 1240 | I21: =IF(F21="","OFFLINE","ONLINE") -> ONLINE | J21: =IF(H21 < 0, "Return", "Sale") -> Sale | K21: =ABS(H21) -> 1240
A22: 46047 | B22: 0.55703704 | C22: POS03 | D22: TXN1021 | E22: C003 | H22: 210 | I22: =IF(F22="","OFFLINE","ONLINE") -> OFFLINE | J22: =IF(H22 < 0, "Return", "Sale") -> Sale | K22: =ABS(H22) -> 210
A23: 46047 | B23: 0.5687037 | C23: POS01 | D23: TXN1022 | E23: C001 | H23: 1840 | I23: =IF(F23="","OFFLINE","ONLINE") -> OFFLINE | J23: =IF(H23 < 0, "Return", "Sale") -> Sale | K23: =ABS(H23) -> 1840
A24: 46047 | B24: 0.58010417 | C24: POS02 | D24: TXN1023 | E24: C002 | H24: -320 | I24: =IF(F24="","OFFLINE","ONLINE") -> OFFLINE | J24: =IF(H24 < 0, "Return", "Sale") -> Return | K24: =ABS(H24) -> 320
A25: 46047 | B25: 0.59012731 | C25: POS03 | D25: TXN1024 | E25: C003 | H25: 540 | I25: =IF(F25="","OFFLINE","ONLINE") -> OFFLINE | J25: =IF(H25 < 0, "Return", "Sale") -> Sale | K25: =ABS(H25) -> 540
A26: 46047 | B26: 0.60038194 | C26: POS01 | D26: TXN1025 | E26: C001 | F26: ORD5006 | G26: TRIP9006 | H26: 2750 | I26: =IF(F26="","OFFLINE","ONLINE") -> ONLINE | J26: =IF(H26 < 0, "Return", "Sale") -> Sale | K26: =ABS(H26) -> 2750
A27: 46047 | B27: 0.61131944 | C27: POS02 | D27: TXN1026 | E27: C002 | H27: 360 | I27: =IF(F27="","OFFLINE","ONLINE") -> OFFLINE | J27: =IF(H27 < 0, "Return", "Sale") -> Sale | K27: =ABS(H27) -> 360
A28: 46047 | B28: 0.62155093 | C28: POS03 | D28: TXN1027 | E28: C003 | H28: 1120 | I28: =IF(F28="","OFFLINE","ONLINE") -> OFFLINE | J28: =IF(H28 < 0, "Return", "Sale") -> Sale | K28: =ABS(H28) -> 1120
A29: 46047 | B29: 0.63320602 | C29: POS01 | D29: TXN1028 | E29: C001 | H29: -450 | I29: =IF(F29="","OFFLINE","ONLINE") -> OFFLINE | J29: =IF(H29 < 0, "Return", "Sale") -> Return | K29: =ABS(H29) -> 450
A30: 46047 | B30: 0.64486111 | C30: POS02 | D30: TXN1029 | E30: C002 | F30: ORD5007 | G30: TRIP9007 | H30: 690 | I30: =IF(F30="","OFFLINE","ONLINE") -> ONLINE | J30: =IF(H30 < 0, "Return", "Sale") -> Sale | K30: =ABS(H30) -> 690
A31: 46047 | B31: 0.65641204 | C31: POS03 | D31: TXN1030 | E31: C003 | H31: 260 | I31: =IF(F31="","OFFLINE","ONLINE") -> OFFLINE | J31: =IF(H31 < 0, "Return", "Sale") -> Sale | K31: =ABS(H31) -> 260
A32: 46047 | B32: 0.66872685 | C32: POS01 | D32: TXN1031 | E32: C001 | H32: 980 | I32: =IF(F32="","OFFLINE","ONLINE") -> OFFLINE | J32: =IF(H32 < 0, "Return", "Sale") -> Sale | K32: =ABS(H32) -> 980
A33: 46047 | B33: 0.67943287 | C33: POS02 | D33: TXN1032 | E33: C002 | H33: 1430 | I33: =IF(F33="","OFFLINE","ONLINE") -> OFFLINE | J33: =IF(H33 < 0, "Return", "Sale") -> Sale | K33: =ABS(H33) -> 1430
A34: 46047 | B34: 0.69075231 | C34: POS03 | D34: TXN1033 | E34: C003 | F34: ORD5008 | G34: TRIP9008 | H34: 4120 | I34: =IF(F34="","OFFLINE","ONLINE") -> ONLINE | J34: =IF(H34 < 0, "Return", "Sale") -> Sale | K34: =ABS(H34) -> 4120
A35: 46047 | B35: 0.70149306 | C35: POS01 | D35: TXN1034 | E35: C001 | H35: 180 | I35: =IF(F35="","OFFLINE","ONLINE") -> OFFLINE | J35: =IF(H35 < 0, "Return", "Sale") -> Sale | K35: =ABS(H35) -> 180
A36: 46047 | B36: 0.71292824 | C36: POS02 | D36: TXN1035 | E36: C002 | H36: -210 | I36: =IF(F36="","OFFLINE","ONLINE") -> OFFLINE | J36: =IF(H36 < 0, "Return", "Sale") -> Return | K36: =ABS(H36) -> 210
A37: 46047 | B37: 0.72423611 | C37: POS03 | D37: TXN1036 | E37: C003 | H37: 760 | I37: =IF(F37="","OFFLINE","ONLINE") -> OFFLINE | J37: =IF(H37 < 0, "Return", "Sale") -> Sale | K37: =ABS(H37) -> 760
A38: 46047 | B38: 0.73574074 | C38: POS01 | D38: TXN1037 | E38: C001 | F38: ORD5009 | G38: TRIP9009 | H38: 990 | I38: =IF(F38="","OFFLINE","ONLINE") -> ONLINE | J38: =IF(H38 < 0, "Return", "Sale") -> Sale | K38: =ABS(H38) -> 990
A39: 46047 | B39: 0.74706019 | C39: POS02 | D39: TXN1038 | E39: C002 | H39: 430 | I39: =IF(F39="","OFFLINE","ONLINE") -> OFFLINE | J39: =IF(H39 < 0, "Return", "Sale") -> Sale | K39: =ABS(H39) -> 430
A40: 46047 | B40: 0.75855324 | C40: POS03 | D40: TXN1039 | E40: C003 | H40: 1580 | I40: =IF(F40="","OFFLINE","ONLINE") -> OFFLINE | J40: =IF(H40 < 0, "Return", "Sale") -> Sale | K40: =ABS(H40) -> 1580
...

Sheet Final_MIS
A1: Daily Store Performance Summary
A2: Total Sales | B2: =SUMIFS(Cleaned_EJ!H:H, Cleaned_EJ!J:J, "Sale") -> 323515
A3: Total Returns | B3: =SUMIFS(Cleaned_EJ!H:H, Cleaned_EJ!J:J, "Return") -> -5720
A4: Net Sales | B4: =B2+B3 -> 317795
A5: Offline Sales | B5: =SUMIFS(Cleaned_EJ!H:H, Cleaned_EJ!J:J, "Sale", Cleaned_EJ!I:I, "Offline") -> 129595
A6: Online Sales | B6: =SUMIFS(Cleaned_EJ!H:H, Cleaned_EJ!J:J, "Sale", Cleaned_EJ!I:I, "Online") -> 193920
A7: Total Transactions | B7: =COUNTA(Cleaned_EJ!C:C) -> 346
A8: Online Order Count | B8: =COUNTIFS(Cleaned_EJ!I:I, "Online") -> 81
A9: Return Transaction Count | B9: =COUNTIFS(Cleaned_EJ!J:J, "Return") -> 26
A10: Return Rate | B10: =B9/B7 -> 0.075144509
A11: High Return Alert | B11: =IF(B9>10, "Review", "Ok") -> Review
A14: Data is simulated for learning purpose
O117: D2: C001
O118: D3: C002
O119: D4: C003
